<?xml version="1.0" ?>
<robot name="rover">
  <link name="base_link"/>
  <link name="chassis_link">
    <visual>
      <geometry>
        <mesh filename="../meshes/rover_chassis.glb"/>
      </geometry>
    </visual>
  </link>
  <joint name="base_link_to_chassis_link" type="fixed">
    <origin rpy="0 0 0" xyz="21.18 0.047903 40.225"/>
    <parent link="base_link"/>
    <child link="chassis_link"/>
  </joint>
  <link name="arm_a_link">
    <visual>
      <geometry>
        <mesh filename="../meshes/arm_a.glb"/>
      </geometry>
    </visual>
  </link>
  <link name="arm_b_link">
    <visual>
      <geometry>
        <mesh filename="../meshes/arm_b.glb"/>
      </geometry>
    </visual>
  </link>
  <link name="arm_c_link">
    <visual>
      <geometry>
        <mesh filename="../meshes/arm_c.glb"/>
      </geometry>
    </visual>
  </link>
  <link name="arm_d_link">
    <visual>
      <geometry>
        <mesh filename="../meshes/arm_d.glb"/>
      </geometry>
    </visual>
  </link>
  <link name="arm_e_link">
    <visual>
      <geometry>
        <mesh filename="../meshes/arm_e.glb"/>
      </geometry>
    </visual>
  </link>
  <link name="arm_gripper_link">
    <visual>
      <geometry>
        <mesh filename="../meshes/arm_gripper.glb"/>
      </geometry>
    </visual>
  </link>
  <joint name="chassis_to_arm_a" type="prismatic">
    <origin rpy="0 0 0" xyz="0 6.5 9.87"/>
    <parent link="chassis_link"/>
    <child link="arm_a_link"/>
    <axis xyz="0 -1 0"/>
    <limit lower="0" upper="40"/>
  </joint>
  <joint name="arm_a_to_arm_b" type="revolute">
    <origin rpy="0 0 0" xyz="4.452 0 5.163"/>
    <parent link="arm_a_link"/>
    <child link="arm_b_link"/>
    <axis xyz="0 1 0"/>
    <limit lower="-1.344" upper="0.2617"/>
  </joint>
  <joint name="arm_b_to_arm_c" type="revolute">
    <origin rpy="0 0 0" xyz="53.271 0 0"/>
    <parent link="arm_b_link"/>
    <child link="arm_c_link"/>
    <axis xyz="0 1 0"/>
    <limit lower="-1.0471" upper="3.0543"/>
  </joint>
  <joint name="arm_c_to_arm_d" type="revolute">
    <origin rpy="0 0 0" xyz="39.525 0 8.329"/>
    <parent link="arm_c_link"/>
    <child link="arm_d_link"/>
    <axis xyz="0 1 0"/>
    <limit lower="-1.1344" upper="1.1344"/>
  </joint>
  <joint name="arm_d_to_arm_e" type="revolute">
    <origin rpy="1.570796 0 0" xyz="0 0 0"/>
    <parent link="arm_d_link"/>
    <child link="arm_e_link"/>
    <axis xyz="1 0 0"/>
    <limit lower="-2.35619" upper="2.35619"/>
  </joint>
  <joint name="arm_e_to_arm_gripper" type="prismatic">
    <origin rpy="0 0 0" xyz="8.375 0 0"/>
    <parent link="arm_e_link"/>
    <child link="arm_gripper_link"/>
    <axis xyz="0 1 0"/>
    <limit lower="0" upper="8.8"/>
    <dynamics damping="1.0"/>
  </joint>
  <link name="front_left_wheel_link">
    <visual>
      <geometry>
        <mesh filename="../meshes/rover_left_wheel.glb"/>
      </geometry>
    </visual>
  </link>
  <link name="center_left_wheel_link">
    <visual>
      <geometry>
        <mesh filename="../meshes/rover_left_wheel.glb"/>
      </geometry>
    </visual>
  </link>
  <link name="back_left_wheel_link">
    <visual>
      <geometry>
        <mesh filename="../meshes/rover_left_wheel.glb"/>
      </geometry>
    </visual>
  </link>
  <link name="left_rocker_link">
    <visual>
      <geometry>
        <mesh filename="../meshes/rover_left_rocker.glb"/>
      </geometry>
    </visual>
  </link>
  <link name="left_lambda_lower_link">
    <visual>
      <geometry>
        <mesh filename="../meshes/rover_left_lambda_lower.glb"/>
      </geometry>
    </visual>
  </link>
  <link name="left_lambda_front_link">
    <visual>
      <geometry>
      <mesh filename="../meshes/rover_left_lambda_front.glb"/>
      </geometry>
    </visual>
  </link>
  <link name="left_lambda_rear_link">
    <visual>
      <geometry>
      <mesh filename="../meshes/rover_left_lambda_rear.glb"/>
      </geometry>
    </visual>
  </link>
  <link name="left_lambda_crank_front_link">
    <visual>
      <geometry>
      <mesh filename="../meshes/rover_front_lambda_crank.glb"/>
      </geometry>
    </visual>
  </link>
  <link name="left_lambda_crank_rear_link">
    <visual>
      <geometry>
      <mesh filename="../meshes/rover_rear_lambda_crank.glb"/>
      </geometry>
    </visual>
  </link>
  <joint name="chassis_to_left_rocker" type="revolute">
    <parent link="chassis_link"/>
    <child link="left_rocker_link"/>
    <origin rpy="0 0 0" xyz="0 29.946 0"/>
    <axis xyz="0 1 0"/>
  </joint>
  <joint name="left_rocker_to_left_lambda_lower" type="revolute">
    <parent link="left_rocker_link"/>
    <child link="left_lambda_lower_link"/>
    <origin rpy="0 0 0" xyz="-27.73 5.577 -15.460"/>
    <axis xyz="0 1 0"/>
  </joint>
  <joint name="left_rocker_to_left_lambda_crank_rear" type="revolute">
    <parent link="left_rocker_link"/>
    <child link="left_lambda_crank_rear_link"/>
    <origin rpy="0 0 0" xyz="-27.73 9.809 -1.220"/>
    <axis xyz="0 1 0"/>
  </joint>
  <joint name="left_rocker_to_left_lambda_crank_front" type="revolute">
    <parent link="left_rocker_link"/>
    <child link="left_lambda_crank_front_link"/>
    <origin rpy="0 0 0" xyz="-27.73 10.760 -1.220"/>
    <axis xyz="0 1 0"/>
  </joint>
  <joint name="left_lambda_lower_to_left_lambda_front" type="revolute">
    <parent link="left_lambda_lower_link"/>
    <child link="left_lambda_front_link"/>
    <origin rpy="0 0 0" xyz="15.755 4.708 5.735"/>
    <axis xyz="0 1 0"/>
  </joint>
  <joint name="left_lambda_lower_to_left_lambda_rear" type="revolute">
    <parent link="left_lambda_lower_link"/>
    <child link="left_lambda_rear_link"/>
    <origin rpy="0 0 0" xyz="-15.755 4.708 5.735"/>
    <axis xyz="0 1 0"/>
  </joint>
  <joint name="left_rocker_to_front_left_wheel" type="continuous">
    <parent link="left_rocker_link"/>
    <child link="front_left_wheel_link"/>
    <origin xyz="34.781 15.7933 -28.303"/>
    <axis xyz="0 1 0"/>
  </joint>
  <joint name="left_lambda_front_to_center_left_wheel" type="continuous">
    <parent link="left_lambda_front_link"/>
    <child link="center_left_wheel_link"/>
    <origin rpy="0 0 0" xyz="11.343 9.594 -18.319"/>
    <axis xyz="0 1 0"/>
  </joint>
  <joint name="left_lambda_rear_to_back_left_wheel" type="continuous">
    <parent link="left_lambda_rear_link"/>
    <child link="back_left_wheel_link"/>
    <origin rpy="0 0 0" xyz="-11.343 9.594 -18.319"/>
    <axis xyz="0 1 0"/>
  </joint>
  <link name="front_right_wheel_link">
    <visual>
      <geometry>
        <mesh filename="../meshes/rover_right_wheel.glb"/>
      </geometry>
    </visual>
  </link>
  <link name="center_right_wheel_link">
    <visual>
      <geometry>
        <mesh filename="../meshes/rover_right_wheel.glb"/>
      </geometry>
    </visual>
  </link>
  <link name="back_right_wheel_link">
    <visual>
      <geometry>
        <mesh filename="../meshes/rover_right_wheel.glb"/>
      </geometry>
    </visual>
  </link>
  <link name="right_rocker_link">
    <visual>
      <geometry>
        <mesh filename="../meshes/rover_right_rocker.glb"/>
      </geometry>
    </visual>
  </link>
  <link name="right_lambda_lower_link">
    <visual>
      <geometry>
        <mesh filename="../meshes/rover_right_lambda_lower.glb"/>
      </geometry>
    </visual>
  </link>
  <link name="right_lambda_front_link">
    <visual>
      <geometry>
      <mesh filename="../meshes/rover_right_lambda_front.glb"/>
      </geometry>
    </visual>
  </link>
  <link name="right_lambda_rear_link">
    <visual>
      <geometry>
      <mesh filename="../meshes/rover_right_lambda_rear.glb"/>
      </geometry>
    </visual>
  </link>
  <link name="right_lambda_crank_front_link">
    <visual>
      <geometry>
      <mesh filename="../meshes/rover_front_lambda_crank.glb"/>
      </geometry>
    </visual>
  </link>
  <link name="right_lambda_crank_rear_link">
    <visual>
      <geometry>
      <mesh filename="../meshes/rover_rear_lambda_crank.glb"/>
      </geometry>
    </visual>
  </link>
  <joint name="chassis_to_right_rocker" type="revolute">
    <parent link="chassis_link"/>
    <child link="right_rocker_link"/>
    <origin rpy="0 0 0" xyz="0 -29.946 0"/>
    <axis xyz="0 1 0"/>
  </joint>
  <joint name="right_rocker_to_right_lambda_lower" type="revolute">
    <parent link="right_rocker_link"/>
    <child link="right_lambda_lower_link"/>
    <origin rpy="0 0 0" xyz="-27.73 -5.577 -15.460"/>
    <axis xyz="0 1 0"/>
  </joint>
  <joint name="right_rocker_to_right_lambda_crank_rear" type="revolute">
    <parent link="right_rocker_link"/>
    <child link="right_lambda_crank_rear_link"/>
    <origin rpy="0 0 0" xyz="-27.73 -9.809 -1.220"/>
    <axis xyz="0 1 0"/>
  </joint>
  <joint name="right_rocker_to_right_lambda_crank_front" type="revolute">
    <parent link="right_rocker_link"/>
    <child link="right_lambda_crank_front_link"/>
    <origin rpy="0 0 0" xyz="-27.73 -10.760 -1.220"/>
    <axis xyz="0 1 0"/>
  </joint>
  <joint name="right_lambda_lower_to_right_lambda_front" type="revolute">
    <parent link="right_lambda_lower_link"/>
    <child link="right_lambda_front_link"/>
    <origin rpy="0 0 0" xyz="15.755 -4.708 5.735"/>
    <axis xyz="0 1 0"/>
  </joint>
  <joint name="right_lambda_lower_to_right_lambda_rear" type="revolute">
    <parent link="right_lambda_lower_link"/>
    <child link="right_lambda_rear_link"/>
    <origin rpy="0 0 0" xyz="-15.755 -4.708 5.735"/>
    <axis xyz="0 1 0"/>
  </joint>
  <joint name="right_rocker_to_front_right_wheel" type="continuous">
    <parent link="right_rocker_link"/>
    <child link="front_right_wheel_link"/>
    <origin xyz="34.781 -15.7933 -28.303"/>
    <axis xyz="0 1 0"/>
  </joint>
  <joint name="right_lambda_front_to_center_right_wheel" type="continuous">
    <parent link="right_lambda_front_link"/>
    <child link="center_right_wheel_link"/>
    <origin rpy="0 0 0" xyz="11.343 -9.594 -18.319"/>
    <axis xyz="0 1 0"/>
  </joint>
  <joint name="right_lambda_rear_to_back_right_wheel" type="continuous">
    <parent link="right_lambda_rear_link"/>
    <child link="back_right_wheel_link"/>
    <origin rpy="0 0 0" xyz="-11.343 -9.594 -18.319"/>
    <axis xyz="0 1 0"/>
  </joint>
</robot>
